Workbook

Sheet MasterData
A1: CEKNIS | B1: CEKNISN | C1: NIS | D1: NISN | E1: NAMA | F1: JK | G1: KELAS | H1: ROMBEL | I1: TINGKAT | J1: TMS | K1: MAIL
A2: =if(len(C2)=4,"OK","INVALID") -> OK | B2: =if(len(D2)=10,"OK","INVALID") -> OK | C2: 7412 | D2: 0064692711 | E2: ABIDA NAFISA SAHDIN | F2: P | G2: =I2&H2 -> PURNA2025-AKL1 | H2: =VLOOKUP($C2,Userpass!$A$2:$L$3001,12,FALSE) -> AKL1 | I2: PURNA2025- | J2: 2022 | K2: =VLOOKUP($C2,Userpass!$A$2:$R$3001,2,FALSE) -> akl20227412.alumni@smkn12malang.sch.id
A3: =if(len(C3)=4,"OK","INVALID") -> OK | B3: =if(len(D3)=10,"OK","INVALID") -> OK | C3: 7417 | D3: 0057327509 | E3: ADAM AGUNG SETIAWAN | F3: L | G3: =I3&H3 -> PURNA2025-AKL1 | H3: =VLOOKUP($C3,Userpass!$A$2:$L$3001,12,FALSE) -> AKL1 | I3: PURNA2025- | J3: 2022 | K3: =VLOOKUP($C3,Userpass!$A$2:$R$3001,2,FALSE) -> akl20227417.alumni@smkn12malang.sch.id
A4: =if(len(C4)=4,"OK","INVALID") -> OK | B4: =if(len(D4)=10,"OK","INVALID") -> OK | C4: 7438 | D4: 0053495891 | E4: AINNUN NASIQA | F4: P | G4: =I4&H4 -> PURNA2025-AKL1 | H4: =VLOOKUP($C4,Userpass!$A$2:$L$3001,12,FALSE) -> AKL1 | I4: PURNA2025- | J4: 2022 | K4: =VLOOKUP($C4,Userpass!$A$2:$R$3001,2,FALSE) -> akl20227438.alumni@smkn12malang.sch.id
A5: =if(len(C5)=4,"OK","INVALID") -> OK | B5: =if(len(D5)=10,"OK","INVALID") -> OK | C5: 7439 | D5: 0069643883 | E5: AINUR ROSIDA | F5: P | G5: =I5&H5 -> PURNA2025-AKL1 | H5: =VLOOKUP($C5,Userpass!$A$2:$L$3001,12,FALSE) -> AKL1 | I5: PURNA2025- | J5: 2022 | K5: =VLOOKUP($C5,Userpass!$A$2:$R$3001,2,FALSE) -> akl20227439.alumni@smkn12malang.sch.id
A6: =if(len(C6)=4,"OK","INVALID") -> OK | B6: =if(len(D6)=10,"OK","INVALID") -> OK | C6: 7452 | D6: 0064107208 | E6: ALSITA NAINA MARDIYAH | F6: P | G6: =I6&H6 -> PURNA2025-AKL1 | H6: =VLOOKUP($C6,Userpass!$A$2:$L$3001,12,FALSE) -> AKL1 | I6: PURNA2025- | J6: 2022 | K6: =VLOOKUP($C6,Userpass!$A$2:$R$3001,2,FALSE) -> akl20227452.alumni@smkn12malang.sch.id
A7: =if(len(C7)=4,"OK","INVALID") -> OK | B7: =if(len(D7)=10,"OK","INVALID") -> OK | C7: 7476 | D7: 0069274624 | E7: ANITA MAUDI PUTRI S. | F7: P | G7: =I7&H7 -> PURNA2025-AKL1 | H7: =VLOOKUP($C7,Userpass!$A$2:$L$3001,12,FALSE) -> AKL1 | I7: PURNA2025- | J7: 2022 | K7: =VLOOKUP($C7,Userpass!$A$2:$R$3001,2,FALSE) -> akl20227476.alumni@smkn12malang.sch.id
A8: =if(len(C8)=4,"OK","INVALID") -> OK | B8: =if(len(D8)=10,"OK","INVALID") -> OK | C8: 7501 | D8: 0063450863 | E8: AULIA RAMADHANI | F8: P | G8: =I8&H8 -> PURNA2025-AKL1 | H8: =VLOOKUP($C8,Userpass!$A$2:$L$3001,12,FALSE) -> AKL1 | I8: PURNA2025- | J8: 2022 | K8: =VLOOKUP($C8,Userpass!$A$2:$R$3001,2,FALSE) -> akl20227501.alumni@smkn12malang.sch.id
A9: =if(len(C9)=4,"OK","INVALID") -> OK | B9: =if(len(D9)=10,"OK","INVALID") -> OK | C9: 7503 | D9: 0068735479 | E9: AXEL RIZKY RAMADHAN SAPUTRI | F9: P | G9: =I9&H9 -> PURNA2025-AKL1 | H9: =VLOOKUP($C9,Userpass!$A$2:$L$3001,12,FALSE) -> AKL1 | I9: PURNA2025- | J9: 2022 | K9: =VLOOKUP($C9,Userpass!$A$2:$R$3001,2,FALSE) -> akl20227503.alumni@smkn12malang.sch.id
A10: =if(len(C10)=4,"OK","INVALID") -> OK | B10: =if(len(D10)=10,"OK","INVALID") -> OK | C10: 7510 | D10: 0079578828 | E10: BALQIS SALSABILLA | F10: P | G10: =I10&H10 -> PURNA2025-AKL1 | H10: =VLOOKUP($C10,Userpass!$A$2:$L$3001,12,FALSE) -> AKL1 | I10: PURNA2025- | J10: 2022 | K10: =VLOOKUP($C10,Userpass!$A$2:$R$3001,2,FALSE) -> akl20227510.alumni@smkn12malang.sch.id
A11: =if(len(C11)=4,"OK","INVALID") -> OK | B11: =if(len(D11)=10,"OK","INVALID") -> OK | C11: 7529 | D11: 0074303312 | E11: CECIL MAULDYA KURNIAWAN | F11: P | G11: =I11&H11 -> PURNA2025-AKL1 | H11: =VLOOKUP($C11,Userpass!$A$2:$L$3001,12,FALSE) -> AKL1 | I11: PURNA2025- | J11: 2022 | K11: =VLOOKUP($C11,Userpass!$A$2:$R$3001,2,FALSE) -> akl20227529.alumni@smkn12malang.sch.id
A12: =if(len(C12)=4,"OK","INVALID") -> OK | B12: =if(len(D12)=10,"OK","INVALID") -> OK | C12: 7539 | D12: 0068045902 | E12: CITRA BELLA | F12: P | G12: =I12&H12 -> PURNA2025-AKL1 | H12: =VLOOKUP($C12,Userpass!$A$2:$L$3001,12,FALSE) -> AKL1 | I12: PURNA2025- | J12: 2022 | K12: =VLOOKUP($C12,Userpass!$A$2:$R$3001,2,FALSE) -> akl20227539.alumni@smkn12malang.sch.id
A13: =if(len(C13)=4,"OK","INVALID") -> OK | B13: =if(len(D13)=10,"OK","INVALID") -> OK | C13: 7561 | D13: 0069261445 | E13: DEVARA ADITYAN LESTARI | F13: P | G13: =I13&H13 -> PURNA2025-AKL1 | H13: =VLOOKUP($C13,Userpass!$A$2:$L$3001,12,FALSE) -> AKL1 | I13: PURNA2025- | J13: 2022 | K13: =VLOOKUP($C13,Userpass!$A$2:$R$3001,2,FALSE) -> akl20227561.alumni@smkn12malang.sch.id
... A223: =if(len(C223)=4,"OK","INVALID") -> OK | B223: =if(len(D223)=10,"OK","INVALID") -> OK | C223: 7560 | D223: 0065322309 | E223: DEVANI CAHYA WARDANIA | F223: P | G223: =I223&H223 -> PURNA2025-DKV2 | H223: =VLOOKUP($C223,Userpass!$A$2:$L$3001,12,FALSE) -> DKV2 | I223: PURNA2025- | J223: 2022 | K223: =VLOOKUP($C223,Userpass!$A$2:$R$3001,2,FALSE) -> dkv20227560.alumni@smkn12malang.sch.id
A224: =if(len(C224)=4,"OK","INVALID") -> OK | B224: =if(len(D224)=10,"OK","INVALID") -> INVALID | C224: 7583 | E224: DWI ANDIKA CAESAR RAMADHANI | F224: L | G224: =I224&H224 -> PURNA2025-DKV2 | H224: =VLOOKUP($C224,Userpass!$A$2:$L$3001,12,FALSE) -> DKV2 | I224: PURNA2025- | J224: 2022 | K224: =VLOOKUP($C224,Userpass!$A$2:$R$3001,2,FALSE) -> dkv20227583.alumni@smkn12malang.sch.id
A225: =if(len(C225)=4,"OK","INVALID") -> OK | B225: =if(len(D225)=10,"OK","INVALID") -> OK | C225: 7585 | D225: 0077885112 | E225: DWI FEBRIAN | F225: L | G225: =I225&H225 -> PURNA2025-DKV2 | H225: =VLOOKUP($C225,Userpass!$A$2:$L$3001,12,FALSE) -> DKV2 | I225: PURNA2025- | J225: 2022 | K225: =VLOOKUP($C225,Userpass!$A$2:$R$3001,2,FALSE) -> dkv20227585.alumni@smkn12malang.sch.id
A226: =if(len(C226)=4,"OK","INVALID") -> OK | B226: =if(len(D226)=10,"OK","INVALID") -> OK | C226: 7598 | D226: 0063291455 | E226: EXEL BUNGA KHARISMA | F226: P | G226: =I226&H226 -> PURNA2025-DKV2 | H226: =VLOOKUP($C226,Userpass!$A$2:$L$3001,12,FALSE) -> DKV2 | I226: PURNA2025- | J226: 2022 | K226: =VLOOKUP($C226,Userpass!$A$2:$R$3001,2,FALSE) -> dkv20227598.alumni@smkn12malang.sch.id
A227: =if(len(C227)=4,"OK","INVALID") -> OK | B227: =if(len(D227)=10,"OK","INVALID") -> OK | C227: 7613 | D227: 0078084303 | E227: FAREL AL JEFADILAH | F227: L | G227: =I227&H227 -> PURNA2025-DKV2 | H227: =VLOOKUP($C227,Userpass!$A$2:$L$3001,12,FALSE) -> DKV2 | I227: PURNA2025- | J227: 2022 | K227: =VLOOKUP($C227,Userpass!$A$2:$R$3001,2,FALSE) -> dkv20227613.alumni@smkn12malang.sch.id
A228: =if(len(C228)=4,"OK","INVALID") -> OK | B228: =if(len(D228)=10,"OK","INVALID") -> OK | C228: 7636 | D228: 0077170524 | E228: FORTUNATA PUSPA ADELFYAR | F228: P | G228: =I228&H228 -> PURNA2025-DKV2 | H228: =VLOOKUP($C228,Userpass!$A$2:$L$3001,12,FALSE) -> DKV2 | I228: PURNA2025- | J228: 2022 | K228: =VLOOKUP($C228,Userpass!$A$2:$R$3001,2,FALSE) -> dkv20227636.alumni@smkn12malang.sch.id
A229: =if(len(C229)=4,"OK","INVALID") -> OK | B229: =if(len(D229)=10,"OK","INVALID") -> OK | C229: 7664 | D229: 0078051875 | E229: INTAN NURAZIS | F229: P | G229: =I229&H229 -> PURNA2025-DKV2 | H229: =VLOOKUP($C229,Userpass!$A$2:$L$3001,12,FALSE) -> DKV2 | I229: PURNA2025- | J229: 2022 | K229: =VLOOKUP($C229,Userpass!$A$2:$R$3001,2,FALSE) -> dkv20227664.alumni@smkn12malang.sch.id
A230: =if(len(C230)=4,"OK","INVALID") -> OK | B230: =if(len(D230)=10,"OK","INVALID") -> OK | C230: 7676 | D230: 0073176349 | E230: JESSICA DWI NASUHA | F230: P | G230: =I230&H230 -> PURNA2025-DKV2 | H230: =VLOOKUP($C230,Userpass!$A$2:$L$3001,12,FALSE) -> DKV2 | I230: PURNA2025- | J230: 2022 | K230: =VLOOKUP($C230,Userpass!$A$2:$R$3001,2,FALSE) -> dkv20227676.alumni@smkn12malang.sch.id
A231: =if(len(C231)=4,"OK","INVALID") -> OK | B231: =if(len(D231)=10,"OK","INVALID") -> OK | C231: 7700 | D231: 0078316873 | E231: LITA MANDASARI SAGITA | F231: P | G231: =I231&H231 -> PURNA2025-DKV2 | H231: =VLOOKUP($C231,Userpass!$A$2:$L$3001,12,FALSE) -> DKV2 | I231: PURNA2025- | J231: 2022 | K231: =VLOOKUP($C231,Userpass!$A$2:$R$3001,2,FALSE) -> dkv20227700.alumni@smkn12malang.sch.id
A232: =if(len(C232)=4,"OK","INVALID") -> OK | B232: =if(len(D232)=10,"OK","INVALID") -> OK | C232: 7707 | D232: 0066082913 | E232: M. FAISAL ULUMUDDIN | F232: L | G232: =I232&H232 -> PURNA2025-DKV2 | H232: =VLOOKUP($C232,Userpass!$A$2:$L$3001,12,FALSE) -> DKV2 | I232: PURNA2025- | J232: 2022 | K232: =VLOOKUP($C232,Userpass!$A$2:$R$3001,2,FALSE) -> dkv20227707.alumni@smkn12malang.sch.id
A233: =if(len(C233)=4,"OK","INVALID") -> OK | B233: =if(len(D233)=10,"OK","INVALID") -> OK | C233: 7714 | D233: 0051658816 | E233: MAISHA AZAHRA | F233: P | G233: =I233&H233 -> PURNA2025-DKV2 | H233: =VLOOKUP($C233,Userpass!$A$2:$L$3001,12,FALSE) -> DKV2 | I233: PURNA2025- | J233: 2022 | K233: =VLOOKUP($C233,Userpass!$A$2:$R$3001,2,FALSE) -> dkv20227714.alumni@smkn12malang.sch.id
A234: =if(len(C234)=4,"OK","INVALID") -> OK | B234: =if(len(D234)=10,"OK","INVALID") -> OK | C234: 7724 | D234: 0061107250 | E234: MAVIRA YUSTIKA AZARINIE | F234: P | G234: =I234&H234 -> PURNA2025-DKV2 | H234: =VLOOKUP($C234,Userpass!$A$2:$L$3001,12,FALSE) -> DKV2 | I234: PURNA2025- | J234: 2022 | K234: =VLOOKUP($C234,Userpass!$A$2:$R$3001,2,FALSE) -> dkv20227724.alumni@smkn12malang.sch.id
A235: =if(len(C235)=4,"OK","INVALID") -> OK | B235: =if(len(D235)=10,"OK","INVALID") -> OK | C235: 7751 | D235: 0078204785 | E235: MOCHAMMAD ZIDANE FEBRIAN PRATAMA | F235: L | G235: =I235&H235 -> PURNA2025-DKV2 | H235: =VLOOKUP($C235,Userpass!$A$2:$L$3001,12,FALSE) -> DKV2 | I235: PURNA2025- | J235: 2022 | K235: =VLOOKUP($C235,Userpass!$A$2:$R$3001,2,FALSE) -> dkv20227751.alumni@smkn12malang.sch.id
A236: =if(len(C236)=4,"OK","INVALID") -> OK | B236: =if(len(D236)=10,"OK","INVALID") -> OK | C236: 7785 | D236: 0074265210 | E236: MUHAMMAD ILYAS JAUHAR | F236: L | G236: =I236&H236 -> PURNA2025-DKV2 | H236: =VLOOKUP($C236,Userpass!$A$2:$L$3001,12,FALSE) -> DKV2 | I236: PURNA2025- | J236: 2022 | K236: =VLOOKUP($C236,Userpass!$A$2:$R$3001,2,FALSE) -> dkv20227785.alumni@smkn12malang.sch.id
... A373: =if(len(C373)=4,"OK","INVALID") -> OK | B373: =if(len(D373)=10,"OK","INVALID") -> OK | C373: 7737 | D373: 0075901628 | E373: MOCH. GALIH UBAYDILLAH | F373: L | G373: =I373&H373 -> PURNA2025-OTO1 | H373: =VLOOKUP($C373,Userpass!$A$2:$L$3001,12,FALSE) -> OTO1 | I373: PURNA2025- | J373: 2022 | K373: =VLOOKUP($C373,Userpass!$A$2:$R$3001,2,FALSE) -> oto20227737.alumni@smkn12malang.sch.id
A374: =if(len(C374)=4,"OK","INVALID") -> OK | B374: =if(len(D374)=10,"OK","INVALID") -> INVALID | C374: 7739 | E374: MOCH. RIKO ANDRIANTO | F374: L | G374: =I374&H374 -> PURNA2025-OTO1 | H374: =VLOOKUP($C374,Userpass!$A$2:$L$3001,12,FALSE) -> OTO1 | I374: PURNA2025- | J374: 2022 | K374: =VLOOKUP($C374,Userpass!$A$2:$R$3001,2,FALSE) -> oto20227739.alumni@smkn12malang.sch.id
A375: =if(len(C375)=4,"OK","INVALID") -> OK | B375: =if(len(D375)=10,"OK","INVALID") -> OK | C375: 7744 | D375: 0076974955 | E375: MOCHAMAD FADJRI AGUSTINO | F375: L | G375: =I375&H375 -> PURNA2025-OTO1 | H375: =VLOOKUP($C375,Userpass!$A$2:$L$3001,12,FALSE) -> OTO1 | I375: PURNA2025- | J375: 2022 | K375: =VLOOKUP($C375,Userpass!$A$2:$R$3001,2,FALSE) -> oto20227744.alumni@smkn12malang.sch.id
A376: =if(len(C376)=4,"OK","INVALID") -> OK | B376: =if(len(D376)=10,"OK","INVALID") -> OK | C376: 7761 | D376: 0076235030 | E376: MUHAMAD AF RIZAL | F376: L | G376: =I376&H376 -> PURNA2025-OTO1 | H376: =VLOOKUP($C376,Userpass!$A$2:$L$3001,12,FALSE) -> OTO1 | I376: PURNA2025- | J376: 2022 | K376: =VLOOKUP($C376,Userpass!$A$2:$R$3001,2,FALSE) -> oto20227761.alumni@smkn12malang.sch.id
A377: =if(len(C377)=4,"OK","INVALID") -> OK | B377: =if(len(D377)=10,"OK","INVALID") -> OK | C377: 7765 | D377: 0069914287 | E377: MUHAMAD RAFLI NUR FADILAH | F377: L | G377: =I377&H377 -> PURNA2025-OTO1 | H377: =VLOOKUP($C377,Userpass!$A$2:$L$3001,12,FALSE) -> OTO1 | I377: PURNA2025- | J377: 2022 | K377: =VLOOKUP($C377,Userpass!$A$2:$R$3001,2,FALSE) -> oto20227765.alumni@smkn12malang.sch.id
A378: =if(len(C378)=4,"OK","INVALID") -> OK | B378: =if(len(D378)=10,"OK","INVALID") -> OK | C378: 7789 | D378: 0053126521 | E378: MUHAMMAD KARUNIAWAN | F378: L | G378: =I378&H378 -> PURNA2025-OTO1 | H378: =VLOOKUP($C378,Userpass!$A$2:$L$3001,12,FALSE) -> OTO1 | I378: PURNA2025- | J378: 2022 | K378: =VLOOKUP($C378,Userpass!$A$2:$R$3001,2,FALSE) -> oto20227789.alumni@smkn12malang.sch.id
A379: =if(len(C379)=4,"OK","INVALID") -> OK | B379: =if(len(D379)=10,"OK","INVALID") -> OK | C379: 7796 | D379: 0074698176 | E379: MUHAMMAD RAFLY REYNALDI | F379: L | G379: =I379&H379 -> PURNA2025-OTO1 | H379: =VLOOKUP($C379,Userpass!$A$2:$L$3001,12,FALSE) -> OTO1 | I379: PURNA2025- | J379: 2022 | K379: =VLOOKUP($C379,Userpass!$A$2:$R$3001,2,FALSE) -> oto20227796.alumni@smkn12malang.sch.id
A380: =if(len(C380)=4,"OK","INVALID") -> OK | B380: =if(len(D380)=10,"OK","INVALID") -> OK | C380: 7839 | D380: 0072586356 | E380: NENDRA AKBAR FIRMANSYAH | F380: L | G380: =I380&H380 -> PURNA2025-OTO1 | H380: =VLOOKUP($C380,Userpass!$A$2:$L$3001,12,FALSE) -> OTO1 | I380: PURNA2025- | J380: 2022 | K380: =VLOOKUP($C380,Userpass!$A$2:$R$3001,2,FALSE) -> oto20227839.alumni@smkn12malang.sch.id
A381: =if(len(C381)=4,"OK","INVALID") -> OK | B381: =if(len(D381)=10,"OK","INVALID") -> OK | C381: 7868 | D381: 0068283658 | E381: RAFIF RADITYA FERNANDO | F381: L | G381: =I381&H381 -> PURNA2025-OTO1 | H381: =VLOOKUP($C381,Userpass!$A$2:$L$3001,12,FALSE) -> OTO1 | I381: PURNA2025- | J381: 2022 | K381: =VLOOKUP($C381,Userpass!$A$2:$R$3001,2,FALSE) -> oto20227868.alumni@smkn12malang.sch.id
A382: =if(len(C382)=4,"OK","INVALID") -> OK | B382: =if(len(D382)=10,"OK","INVALID") -> OK | C382: 7872 | D382: 0062706443 | E382: RAHEL DIMAS PRAYOGA | F382: L | G382: =I382&H382 -> PURNA2025-OTO1 | H382: =VLOOKUP($C382,Userpass!$A$2:$L$3001,12,FALSE) -> OTO1 | I382: PURNA2025- | J382: 2022 | K382: =VLOOKUP($C382,Userpass!$A$2:$R$3001,2,FALSE) -> oto20227872.alumni@smkn12malang.sch.id
A383: =if(len(C383)=4,"OK","INVALID") -> OK | B383: =if(len(D383)=10,"OK","INVALID") -> OK | C383: 7895 | D383: 0074263156 | E383: RENDI SATYADIBRATA | F383: L | G383: =I383&H383 -> PURNA2025-OTO1 | H383: =VLOOKUP($C383,Userpass!$A$2:$L$3001,12,FALSE) -> OTO1 | I383: PURNA2025- | J383: 2022 | K383: =VLOOKUP($C383,Userpass!$A$2:$R$3001,2,FALSE) -> oto20227895.alumni@smkn12malang.sch.id
A384: =if(len(C384)=4,"OK","INVALID") -> OK | B384: =if(len(D384)=10,"OK","INVALID") -> OK | C384: 7910 | D384: 0075064114 | E384: RIF'AL BAAQI RIZQI | F384: L | G384: =I384&H384 -> PURNA2025-OTO1 | H384: =VLOOKUP($C384,Userpass!$A$2:$L$3001,12,FALSE) -> OTO1 | I384: PURNA2025- | J384: 2022 | K384: =VLOOKUP($C384,Userpass!$A$2:$R$3001,2,FALSE) -> oto20227910.alumni@smkn12malang.sch.id
A385: =if(len(C385)=4,"OK","INVALID") -> OK | B385: =if(len(D385)=10,"OK","INVALID") -> OK | C385: 7926 | D385: 0068910207 | E385: ROBI TANAMAL | F385: L | G385: =I385&H385 -> PURNA2025-OTO1 | H385: =VLOOKUP($C385,Userpass!$A$2:$L$3001,12,FALSE) -> OTO1 | I385: PURNA2025- | J385: 2022 | K385: =VLOOKUP($C385,Userpass!$A$2:$R$3001,2,FALSE) -> oto20227926.alumni@smkn12malang.sch.id
...

Sheet Userpass
A1: profile_field_nis | B1: username | C1: password | D1: email | E1: firstname | F1: lastname | G1: institution | H1: department | I1: city | J1: country | K1: profile_field_tms | L1: profile_field_rmbl | M1: profile_field_nisn | N1: profile_field_lahir | O1: profile_field_nik | P1: checkup | Q1: checkout
A2: 8669 | B2: oto20248669.siswa@smkn12malang.sch.id | C2: fD*?*2&k?ZW{ | D2: oto20248669.siswa@smkn12malang.sch.id | E2: AHMAD SIFAUL QOLBI | F2: =H2&L2 -> DROPOUT | G2: SMK NEGERI 12 MALANG | H2: DROP | I2: MALANG | J2: ID | K2: 192024 | L2: OUT | M2: 0083714798 | P2: =VLOOKUP($A2,MasterData!$C$1:$I$3001,1,FALSE) -> 8669 | Q2: =if(P2=A2,F2,"OUT") -> DROPOUT
A3: 8056 | B3: oto20238056.siswa@smkn12malang.sch.id | C3: [EtKv8vQ?}Jp | D3: oto20238056.siswa@smkn12malang.sch.id | E3: AKBAR ARFIYAN AKHMAD | F3: =H3&L3 -> DROPOUT | G3: SMK NEGERI 12 MALANG | H3: DROP | I3: MALANG | J3: ID | K3: 182023 | L3: OUT | M3: 0077944026 | N3: Not set | O3: 0 | P3: =VLOOKUP($A3,MasterData!$C$1:$I$3001,1,FALSE) -> 8056 | Q3: =if(P3=A3,F3,"OUT") -> DROPOUT
A4: 8109 | B4: oto20238109.siswa@smkn12malang.sch.id | C4: hhex]SV/&EK7 | D4: oto20238109.siswa@smkn12malang.sch.id | E4: ARFI ARDIANSYAH | F4: =H4&L4 -> DROPOUT | G4: SMK NEGERI 12 MALANG | H4: DROP | I4: MALANG | J4: ID | K4: 182023 | L4: OUT | M4: 0072615517 | N4: Not set | O4: 0 | P4: =VLOOKUP($A4,MasterData!$C$1:$I$3001,1,FALSE) -> 8109 | Q4: =if(P4=A4,F4,"OUT") -> DROPOUT
A5: 8143 | B5: jkt20238143.siswa@smkn12malang.sch.id | C5: z?PW2]2-*rs( | D5: jkt20238143.siswa@smkn12malang.sch.id | E5: BUNGA MEGA CITRA SARI | F5: =H5&L5 -> DROPOUT | G5: SMK NEGERI 12 MALANG | H5: DROP | I5: MALANG | J5: ID | K5: 182023 | L5: OUT | M5: 0067105649 | N5: 5 August 2006 | O5: 3507244508060001 | P5: =VLOOKUP($A5,MasterData!$C$1:$I$3001,1,FALSE) -> 8143 | Q5: =if(P5=A5,F5,"OUT") -> DROPOUT
A6: 8178 | B6: klr20238178.siswa@smkn12malang.sch.id | C6: KGHw^+fQmzn8 | D6: klr20238178.siswa@smkn12malang.sch.id | E6: DENDA WIGUNA JAYA DIKARTA | F6: =H6&L6 -> DROPOUT | G6: SMK NEGERI 12 MALANG | H6: DROP | I6: MALANG | J6: ID | K6: 182023 | L6: OUT | M6: 0075980857 | N6: Not set | O6: 0 | P6: =VLOOKUP($A6,MasterData!$C$1:$I$3001,1,FALSE) -> 8178 | Q6: =if(P6=A6,F6,"OUT") -> DROPOUT
A7: 8799 | B7: jkt20248799.siswa@smkn12malang.sch.id | C7: y2&R@*2RC&Zh | D7: jkt20248799.siswa@smkn12malang.sch.id | E7: DINA PUTRI RAMADHANI | F7: =H7&L7 -> DROPOUT | G7: SMK NEGERI 12 MALANG | H7: DROP | I7: MALANG | J7: ID | K7: 192024 | L7: OUT | M7: 0085200236 | P7: =VLOOKUP($A7,MasterData!$C$1:$I$3001,1,FALSE) -> 8799 | Q7: =if(P7=A7,F7,"OUT") -> DROPOUT
A8: 8800 | B8: jkt20248800.siswa@smkn12malang.sch.id | C8: N8Qjww}?AjGC | D8: jkt20248800.siswa@smkn12malang.sch.id | E8: DINAR MAULITA | F8: =H8&L8 -> DROPOUT | G8: SMK NEGERI 12 MALANG | H8: DROP | I8: MALANG | J8: ID | K8: 192024 | L8: OUT | M8: 0085878719 | P8: =VLOOKUP($A8,MasterData!$C$1:$I$3001,1,FALSE) -> 8800 | Q8: =if(P8=A8,F8,"OUT") -> DROPOUT
A9: 8199 | B9: jkt20238199.siswa@smkn12malang.sch.id | C9: V/Lqa3ZU+aVe | D9: jkt20238199.siswa@smkn12malang.sch.id | E9: DIVA PUTRI ANANTA | F9: =H9&L9 -> DROPOUT | G9: SMK NEGERI 12 MALANG | H9: DROP | I9: MALANG | J9: ID | K9: 182023 | L9: OUT | M9: 0074377224 | N9: Not set | O9: 0 | P9: =VLOOKUP($A9,MasterData!$C$1:$I$3001,1,FALSE) -> 8199 | Q9: =if(P9=A9,F9,"OUT") -> DROPOUT
A10: 8809 | B10: klr20248809.siswa@smkn12malang.sch.id | C10: %8pgw].r{.^U | D10: klr20248809.siswa@smkn12malang.sch.id | E10: DOMMINIQUE BRENDA THEOPHANIA SANTOSA | F10: =H10&L10 -> DROPOUT | G10: SMK NEGERI 12 MALANG | H10: DROP | I10: MALANG | J10: ID | K10: 192024 | L10: OUT | M10: 0095067721 | P10: =VLOOKUP($A10,MasterData!$C$1:$I$3001,1,FALSE) -> 8809 | Q10: =if(P10=A10,F10,"OUT") -> DROPOUT
A11: 8277 | B11: oto20238277.siswa@smkn12malang.sch.id | C11: $&w2(X(uV2_b | D11: oto20238277.siswa@smkn12malang.sch.id | E11: HANIF RASHIN MARFADI | F11: =H11&L11 -> DROPOUT | G11: SMK NEGERI 12 MALANG | H11: DROP | I11: MALANG | J11: ID | K11: 182023 | L11: OUT | M11: 0089142622 | N11: Not set | O11: 0 | P11: =VLOOKUP($A11,MasterData!$C$1:$I$3001,1,FALSE) -> 8277 | Q11: =if(P11=A11,F11,"OUT") -> DROPOUT
A12: 8887 | B12: bcf20248887.siswa@smkn12malang.sch.id | C12: 7U8?)shr(ym@ | D12: bcf20248887.siswa@smkn12malang.sch.id | E12: HUZEIN AMILUHUR | F12: =H12&L12 -> DROPOUT | G12: SMK NEGERI 12 MALANG | H12: DROP | I12: MALANG | J12: ID | K12: 192024 | L12: OUT | M12: 0093377553 | P12: =VLOOKUP($A12,MasterData!$C$1:$I$3001,1,FALSE) -> 8887 | Q12: =if(P12=A12,F12,"OUT") -> DROPOUT
A13: 9244 | B13: plg20239244.siswa@smkn12malang.sch.id | C13: bEhS8*sDG(xN | D13: plg20239244.siswa@smkn12malang.sch.id | E13: MARYAM ALHAIFA | F13: =H13&L13 -> DROPOUT | G13: SMK NEGERI 12 MALANG | H13: DROP | I13: MALANG | J13: ID | K13: 182023 | L13: OUT | P13: =VLOOKUP($A13,MasterData!$C$1:$I$3001,1,FALSE) -> 9244 | Q13: =if(P13=A13,F13,"OUT") -> DROPOUT
A14: 9244 | B14: plg20239244.siswa@smkn12malang.sch.id | C14: bEhS8*sDG(xN | D14: plg20239244.siswa@smkn12malang.sch.id | E14: MARYAM ALHAIFA | F14: =H14&L14 -> DROPOUT | G14: SMK NEGERI 12 MALANG | H14: DROP | I14: MALANG | J14: ID | K14: 182023 | L14: OUT | P14: =VLOOKUP($A14,MasterData!$C$1:$I$3001,1,FALSE) -> 9244 | Q14: =if(P14=A14,F14,"OUT") -> DROPOUT
A15: 8962 | B15: klr20248962.siswa@smkn12malang.sch.id | C15: 5($C2xGngT!a | D15: klr20248962.siswa@smkn12malang.sch.id | E15: MAURA LUVIA REVALINA | F15: =H15&L15 -> DROPOUT | G15: SMK NEGERI 12 MALANG | H15: DROP | I15: MALANG | J15: ID | K15: 192024 | L15: OUT | M15: 0086933008 | P15: =VLOOKUP($A15,MasterData!$C$1:$I$3001,1,FALSE) -> 8962 | Q15: =if(P15=A15,F15,"OUT") -> DROPOUT
A16: 8978 | B16: jkt20248978.siswa@smkn12malang.sch.id | C16: NRh$dE]y3krG | D16: jkt20248978.siswa@smkn12malang.sch.id | E16: MOCHAMMAD INDRA | F16: =H16&L16 -> DROPOUT | G16: SMK NEGERI 12 MALANG | H16: DROP | I16: MALANG | J16: ID | K16: 192024 | L16: OUT | M16: 0066829367 | P16: =VLOOKUP($A16,MasterData!$C$1:$I$3001,1,FALSE) -> 8978 | Q16: =if(P16=A16,F16,"OUT") -> DROPOUT
A17: 8984 | B17: oto20248984.siswa@smkn12malang.sch.id | C17: j$T(x7tv9?pe | D17: oto20248984.siswa@smkn12malang.sch.id | E17: MOH ANDHIKA NURHIDAYAH | F17: =H17&L17 -> DROPOUT | G17: SMK NEGERI 12 MALANG | H17: DROP | I17: MALANG | J17: ID | K17: 192024 | L17: OUT | M17: 0085304064 | P17: =VLOOKUP($A17,MasterData!$C$1:$I$3001,1,FALSE) -> 8984 | Q17: =if(P17=A17,F17,"OUT") -> DROPOUT
A18: 9001 | B18: dkv20249001.siswa@smkn12malang.sch.id | C18: _jXeN4*Z)[R% | D18: dkv20249001.siswa@smkn12malang.sch.id | E18: MUHAMMAD ALFA RIZKY ROMADHON | F18: =H18&L18 -> DROPOUT | G18: SMK NEGERI 12 MALANG | H18: DROP | I18: MALANG | J18: ID | K18: 192024 | L18: OUT | M18: 0071314193 | P18: =VLOOKUP($A18,MasterData!$C$1:$I$3001,1,FALSE) -> 9001 | Q18: =if(P18=A18,F18,"OUT") -> DROPOUT
A19: 8426 | B19: jkt20238426.siswa@smkn12malang.sch.id | C19: Uy9&9_HSpHpc | D19: jkt20238426.siswa@smkn12malang.sch.id | E19: MUHAMMAD PRADITYO PUTRA | F19: =H19&L19 -> DROPOUT | G19: SMK NEGERI 12 MALANG | H19: DROP | I19: MALANG | J19: ID | K19: 182023 | L19: OUT | M19: 0064850380 | N19: Not set | O19: 0 | P19: =VLOOKUP($A19,MasterData!$C$1:$I$3001,1,FALSE) -> 8426 | Q19: =if(P19=A19,F19,"OUT") -> DROPOUT
A20: 8464 | B20: oto20238464.siswa@smkn12malang.sch.id | C20: vC8=q)7(qRdN | D20: oto20238464.siswa@smkn12malang.sch.id | E20: NIZAR FAIRUS MADA | F20: =H20&L20 -> DROPOUT | G20: SMK NEGERI 12 MALANG | H20: DROP | I20: MALANG | J20: ID | K20: 182023 | L20: OUT | M20: 0079605954 | N20: Not set | O20: 0 | P20: =VLOOKUP($A20,MasterData!$C$1:$I$3001,1,FALSE) -> 8464 | Q20: =if(P20=A20,F20,"OUT") -> DROPOUT
A21: 9121 | B21: oto20249121.siswa@smkn12malang.sch.id | C21: qs}D}TzEJ2FM | D21: oto20249121.siswa@smkn12malang.sch.id | E21: RENDY DWI ADITYA | F21: =H21&L21 -> DROPOUT | G21: SMK NEGERI 12 MALANG | H21: DROP | I21: MALANG | J21: ID | K21: 192024 | L21: OUT | M21: 0093036834 | P21: =VLOOKUP($A21,MasterData!$C$1:$I$3001,1,FALSE) -> 9121 | Q21: =if(P21=A21,F21,"OUT") -> DROPOUT
A22: 9144 | B22: jkt20249144.siswa@smkn12malang.sch.id | C22: 626-4_yQX%Nu | D22: jkt20249144.siswa@smkn12malang.sch.id | E22: RIZKY FAJAR PRASETYO | F22: =H22&L22 -> DROPOUT | G22: SMK NEGERI 12 MALANG | H22: DROP | I22: MALANG | J22: ID | K22: 192024 | L22: OUT | M22: 0098122282 | P22: =VLOOKUP($A22,MasterData!$C$1:$I$3001,1,FALSE) -> 9144 | Q22: =if(P22=A22,F22,"OUT") -> DROPOUT
A23: 8578 | B23: bcf20238578.siswa@smkn12malang.sch.id | C23: &Um}Q8%5y${p | D23: bcf20238578.siswa@smkn12malang.sch.id | E23: TANTIKA APRILIA | F23: =H23&L23 -> DROPOUT | G23: SMK NEGERI 12 MALANG | H23: DROP | I23: MALANG | J23: ID | K23: 182023 | L23: OUT | M23: 0087390112 | N23: Not set | O23: 0 | P23: =VLOOKUP($A23,MasterData!$C$1:$I$3001,1,FALSE) -> 8578 | Q23: =if(P23=A23,F23,"OUT") -> DROPOUT
A24: 9210 | B24: plg20249210.siswa@smkn12malang.sch.id | C24: 2rH[Y*FmAJ=) | D24: plg20249210.siswa@smkn12malang.sch.id | E24: VIRA ADHA DETALYA | F24: =H24&L24 -> DROPOUT | G24: SMK NEGERI 12 MALANG | H24: DROP | I24: MALANG | J24: ID | K24: 192024 | L24: OUT | M24: 3081520610 | P24: =VLOOKUP($A24,MasterData!$C$1:$I$3001,1,FALSE) -> 9210 | Q24: =if(P24=A24,F24,"OUT") -> DROPOUT
A25: 9231 | B25: oto20249231.siswa@smkn12malang.sch.id | C25: y52.Ax=F&+/c | D25: oto20249231.siswa@smkn12malang.sch.id | E25: ZAHRONI PUTRA WAHYUDI | F25: =H25&L25 -> DROPOUT | G25: SMK NEGERI 12 MALANG | H25: DROP | I25: MALANG | J25: ID | K25: 192024 | L25: OUT | M25: 0088457313 | P25: =VLOOKUP($A25,MasterData!$C$1:$I$3001,1,FALSE) -> 9231 | Q25: =if(P25=A25,F25,"OUT") -> DROPOUT
A26: 7412 | B26: akl20227412.alumni@smkn12malang.sch.id | C26: 4{74rk[)pYJT | D26: akl20227412.siswa@smkn12malang.sch.id | E26: ABIDA NAFISA SAHDIN | F26: =H26&L26 -> PURNA2025-AKL1 | G26: SMK NEGERI 12 MALANG | H26: PURNA2025- | I26: MALANG | J26: ID | K26: 172022 | L26: AKL1 | M26: 0064692711 | N26: Not set | P26: =VLOOKUP($A26,MasterData!$C$1:$I$1995,1,FALSE) -> 7412 | Q26: =if(P26=A26,F26,"OUT") -> PURNA2025-AKL1
A27: 7417 | B27: akl20227417.alumni@smkn12malang.sch.id | C27: 6_tv_ZeUWdHC | D27: akl20227417.siswa@smkn12malang.sch.id | E27: ADAM AGUNG SETIAWAN | F27: =H27&L27 -> PURNA2025-AKL1 | G27: SMK NEGERI 12 MALANG | H27: PURNA2025- | I27: MALANG | J27: ID | K27: 172022 | L27: AKL1 | M27: 0057327509 | N27: Not set | P27: =VLOOKUP($A27,MasterData!$C$1:$I$1995,1,FALSE) -> 7417 | Q27: =if(P27=A27,F27,"OUT") -> PURNA2025-AKL1
A28: 7438 | B28: akl20227438.alumni@smkn12malang.sch.id | C28: L5?(a!nAvbC/ | D28: akl20227438.siswa@smkn12malang.sch.id | E28: AINNUN NASIQA | F28: =H28&L28 -> PURNA2025-AKL1 | G28: SMK NEGERI 12 MALANG | H28: PURNA2025- | I28: MALANG | J28: ID | K28: 172022 | L28: AKL1 | M28: 0053495891 | N28: Not set | P28: =VLOOKUP($A28,MasterData!$C$1:$I$1995,1,FALSE) -> 7438 | Q28: =if(P28=A28,F28,"OUT") -> PURNA2025-AKL1
A29: 7439 | B29: akl20227439.alumni@smkn12malang.sch.id | C29: )yY%*Grn4(2b | D29: akl20227439.siswa@smkn12malang.sch.id | E29: AINUR ROSIDA | F29: =H29&L29 -> PURNA2025-AKL1 | G29: SMK NEGERI 12 MALANG | H29: PURNA2025- | I29: MALANG | J29: ID | K29: 172022 | L29: AKL1 | M29: 0069643883 | N29: Not set | P29: =VLOOKUP($A29,MasterData!$C$1:$I$1995,1,FALSE) -> 7439 | Q29: =if(P29=A29,F29,"OUT") -> PURNA2025-AKL1
A30: 7452 | B30: akl20227452.alumni@smkn12malang.sch.id | C30: bXm_PTbVVw8q | D30: akl20227452.siswa@smkn12malang.sch.id | E30: ALSITA NAINA MARDIYAH | F30: =H30&L30 -> PURNA2025-AKL1 | G30: SMK NEGERI 12 MALANG | H30: PURNA2025- | I30: MALANG | J30: ID | K30: 172022 | L30: AKL1 | M30: 0064107208 | N30: Not set | P30: =VLOOKUP($A30,MasterData!$C$1:$I$1995,1,FALSE) -> 7452 | Q30: =if(P30=A30,F30,"OUT") -> PURNA2025-AKL1
A31: 7476 | B31: akl20227476.alumni@smkn12malang.sch.id | C31: qQ?+wtn&d5{$ | D31: akl20227476.siswa@smkn12malang.sch.id | E31: ANITA MAUDI PUTRI S. | F31: =H31&L31 -> PURNA2025-AKL1 | G31: SMK NEGERI 12 MALANG | H31: PURNA2025- | I31: MALANG | J31: ID | K31: 172022 | L31: AKL1 | M31: 0069274624 | N31: Not set | P31: =VLOOKUP($A31,MasterData!$C$1:$I$1995,1,FALSE) -> 7476 | Q31: =if(P31=A31,F31,"OUT") -> PURNA2025-AKL1
A32: 7501 | B32: akl20227501.alumni@smkn12malang.sch.id | C32: s!H6C2Uz!d.7 | D32: akl20227501.siswa@smkn12malang.sch.id | E32: AULIA RAMADHANI | F32: =H32&L32 -> PURNA2025-AKL1 | G32: SMK NEGERI 12 MALANG | H32: PURNA2025- | I32: MALANG | J32: ID | K32: 172022 | L32: AKL1 | M32: 0063450863 | N32: Not set | P32: =VLOOKUP($A32,MasterData!$C$1:$I$1995,1,FALSE) -> 7501 | Q32: =if(P32=A32,F32,"OUT") -> PURNA2025-AKL1
A33: 7503 | B33: akl20227503.alumni@smkn12malang.sch.id | C33: HejG4{Lqa!]H | D33: akl20227503.siswa@smkn12malang.sch.id | E33: AXEL RIZKY RAMADHAN SAPUTRI | F33: =H33&L33 -> PURNA2025-AKL1 | G33: SMK NEGERI 12 MALANG | H33: PURNA2025- | I33: MALANG | J33: ID | K33: 172022 | L33: AKL1 | M33: 0068735479 | N33: Not set | P33: =VLOOKUP($A33,MasterData!$C$1:$I$1995,1,FALSE) -> 7503 | Q33: =if(P33=A33,F33,"OUT") -> PURNA2025-AKL1
A34: 7510 | B34: akl20227510.alumni@smkn12malang.sch.id | C34: /c29r)-R%X{) | D34: akl20227510.siswa@smkn12malang.sch.id | E34: BALQIS SALSABILLA | F34: =H34&L34 -> PURNA2025-AKL1 | G34: SMK NEGERI 12 MALANG | H34: PURNA2025- | I34: MALANG | J34: ID | K34: 172022 | L34: AKL1 | M34: 0079578828 | N34: Not set | P34: =VLOOKUP($A34,MasterData!$C$1:$I$1995,1,FALSE) -> 7510 | Q34: =if(P34=A34,F34,"OUT") -> PURNA2025-AKL1
A35: 7529 | B35: akl20227529.alumni@smkn12malang.sch.id | C35: 3/pNekb&crZn | D35: akl20227529.siswa@smkn12malang.sch.id | E35: CECIL MAULDYA KURNIAWAN | F35: =H35&L35 -> PURNA2025-AKL1 | G35: SMK NEGERI 12 MALANG | H35: PURNA2025- | I35: MALANG | J35: ID | K35: 172022 | L35: AKL1 | M35: 0074303312 | N35: Not set | P35: =VLOOKUP($A35,MasterData!$C$1:$I$1995,1,FALSE) -> 7529 | Q35: =if(P35=A35,F35,"OUT") -> PURNA2025-AKL1
A36: 7539 | B36: akl20227539.alumni@smkn12malang.sch.id | C36: .B)%Awvbk7)& | D36: akl20227539.siswa@smkn12malang.sch.id | E36: CITRA BELLA | F36: =H36&L36 -> PURNA2025-AKL1 | G36: SMK NEGERI 12 MALANG | H36: PURNA2025- | I36: MALANG | J36: ID | K36: 172022 | L36: AKL1 | M36: 0068045902 | N36: Not set | P36: =VLOOKUP($A36,MasterData!$C$1:$I$1995,1,FALSE) -> 7539 | Q36: =if(P36=A36,F36,"OUT") -> PURNA2025-AKL1
A37: 7561 | B37: akl20227561.alumni@smkn12malang.sch.id | C37: (Qr6[gV6xG{V | D37: akl20227561.siswa@smkn12malang.sch.id | E37: DEVARA ADITYAN LESTARI | F37: =H37&L37 -> PURNA2025-AKL1 | G37: SMK NEGERI 12 MALANG | H37: PURNA2025- | I37: MALANG | J37: ID | K37: 172022 | L37: AKL1 | M37: 0069261445 | N37: Not set | P37: =VLOOKUP($A37,MasterData!$C$1:$I$1995,1,FALSE) -> 7561 | Q37: =if(P37=A37,F37,"OUT") -> PURNA2025-AKL1
... A247: 7560 | B247: dkv20227560.alumni@smkn12malang.sch.id | C247: q9k2rVJh)mh@ | D247: dkv20227560.siswa@smkn12malang.sch.id | E247: DEVANI CAHYA WARDANIA | F247: =H247&L247 -> PURNA2025-DKV2 | G247: SMK NEGERI 12 MALANG | H247: PURNA2025- | I247: MALANG | J247: ID | K247: 172022 | L247: DKV2 | M247: 0065322309 | N247: Not set | P247: =VLOOKUP($A247,MasterData!$C$1:$I$1995,1,FALSE) -> 7560 | Q247: =if(P247=A247,F247,"OUT") -> PURNA2025-DKV2
A248: 7583 | B248: dkv20227583.alumni@smkn12malang.sch.id | C248: QA6X9DsM3{LB | D248: dkv20227583.siswa@smkn12malang.sch.id | E248: DWI ANDIKA CAESAR RAMADHANI | F248: =H248&L248 -> PURNA2025-DKV2 | G248: SMK NEGERI 12 MALANG | H248: PURNA2025- | I248: MALANG | J248: ID | K248: 172022 | L248: DKV2 | N248: Not set | P248: =VLOOKUP($A248,MasterData!$C$1:$I$1995,1,FALSE) -> 7583 | Q248: =if(P248=A248,F248,"OUT") -> PURNA2025-DKV2
A249: 7585 | B249: dkv20227585.alumni@smkn12malang.sch.id | C249: SFcdv3vvF-Um | D249: dkv20227585.siswa@smkn12malang.sch.id | E249: DWI FEBRIAN | F249: =H249&L249 -> PURNA2025-DKV2 | G249: SMK NEGERI 12 MALANG | H249: PURNA2025- | I249: MALANG | J249: ID | K249: 172022 | L249: DKV2 | M249: 0077885112 | N249: Not set | P249: =VLOOKUP($A249,MasterData!$C$1:$I$1995,1,FALSE) -> 7585 | Q249: =if(P249=A249,F249,"OUT") -> PURNA2025-DKV2
...

Sheet CetakUserpass
D1: PEMERINTAH PROVINSI JAWA TIMUR
D2: SMK NEGERI 12 MALANG
D3: Jl. Pahlawan, Balearjosari, Blimbing, Kota Malang, Jawa Timur 65126
D4: Telepon (0341) 400884, Faksimile (0341) 400884
D5: Laman: https://smkn12malang.sch.id, Pos-el: surat@smkn12malang.sch.id
D7: DAFTAR AKUN DARING SISWA
D8: TAHUN PELAJARAN 2024/2025
B11: Wali Kelas: | C11: =VLOOKUP(N11,Walas!A2:B89,2,FALSE) -> HADI PURWANTO, S.Pd | M11: Kelas: | N11: XTKR2
A13: NO | B13: NIS | C13: NISN | D13: NAMA | E13: L/P | F13: Username | M13: Password | P13: KET
A14: 1 | B14: =IFERROR(__xludf.DUMMYFUNCTION("FILTER(MasterData!$C$2:$F$2400,MasterData!$G$2:$G$2400=N11)"),9255.0) -> 9255 | C14: =IFERROR(__xludf.DUMMYFUNCTION("""COMPUTED_VALUE"""),"3093981612") -> 3093981612 | D14: =IFERROR(__xludf.DUMMYFUNCTION("""COMPUTED_VALUE"""),"ACHMAD FELIX DZIKRULLAH") -> ACHMAD FELIX DZIKRULLAH | F14: =VLOOKUP($B14,Userpass!$A$2:$E$3001,2,FALSE) -> tkr20259255.siswa@smkn12malang.sch.id | M14: =VLOOKUP($B14,Userpass!$A$2:$E$3001,3,FALSE) -> (shWB33G
A15: 2 | B15: =IFERROR(__xludf.DUMMYFUNCTION("""COMPUTED_VALUE"""),9260.0) -> 9260 | C15: =IFERROR(__xludf.DUMMYFUNCTION("""COMPUTED_VALUE"""),"0097385091") -> 0097385091 | D15: =IFERROR(__xludf.DUMMYFUNCTION("""COMPUTED_VALUE"""),"ADHISTIRA WIDAYADILLAH") -> ADHISTIRA WIDAYADILLAH | F15: =VLOOKUP($B15,Userpass!$A$2:$E$3001,2,FALSE) -> tkr20259260.siswa@smkn12malang.sch.id | M15: =VLOOKUP($B15,Userpass!$A$2:$E$3001,3,FALSE) -> 3L6fAy@5
A16: 3 | B16: =IFERROR(__xludf.DUMMYFUNCTION("""COMPUTED_VALUE"""),9284.0) -> 9284 | C16: =IFERROR(__xludf.DUMMYFUNCTION("""COMPUTED_VALUE"""),"3104958814") -> 3104958814 | D16: =IFERROR(__xludf.DUMMYFUNCTION("""COMPUTED_VALUE"""),"AHMAD RAHMAD AFANDI") -> AHMAD RAHMAD AFANDI | F16: =VLOOKUP($B16,Userpass!$A$2:$E$3001,2,FALSE) -> tkr20259284.siswa@smkn12malang.sch.id | M16: =VLOOKUP($B16,Userpass!$A$2:$E$3001,3,FALSE) -> %dwjFZ4q
A17: 4 | B17: =IFERROR(__xludf.DUMMYFUNCTION("""COMPUTED_VALUE"""),9296.0) -> 9296 | C17: =IFERROR(__xludf.DUMMYFUNCTION("""COMPUTED_VALUE"""),"0096580518") -> 0096580518 | D17: =IFERROR(__xludf.DUMMYFUNCTION("""COMPUTED_VALUE"""),"AKSEL SUASTUSAIS VERNANDES") -> AKSEL SUASTUSAIS VERNANDES | F17: =VLOOKUP($B17,Userpass!$A$2:$E$3001,2,FALSE) -> tkr20259296.siswa@smkn12malang.sch.id | M17: =VLOOKUP($B17,Userpass!$A$2:$E$3001,3,FALSE) -> J9KFMKm@
A18: 5 | B18: =IFERROR(__xludf.DUMMYFUNCTION("""COMPUTED_VALUE"""),9307.0) -> 9307 | C18: =IFERROR(__xludf.DUMMYFUNCTION("""COMPUTED_VALUE"""),"0109324966") -> 0109324966 | D18: =IFERROR(__xludf.DUMMYFUNCTION("""COMPUTED_VALUE"""),"ALMIRA NURUL QOLBI") -> ALMIRA NURUL QOLBI | F18: =VLOOKUP($B18,Userpass!$A$2:$E$3001,2,FALSE) -> tkr20259307.siswa@smkn12malang.sch.id | M18: =VLOOKUP($B18,Userpass!$A$2:$E$3001,3,FALSE) -> 8@bQq7Ja
A19: 6 | B19: =IFERROR(__xludf.DUMMYFUNCTION("""COMPUTED_VALUE"""),9319.0) -> 9319 | C19: =IFERROR(__xludf.DUMMYFUNCTION("""COMPUTED_VALUE"""),"0091081451") -> 0091081451 | D19: =IFERROR(__xludf.DUMMYFUNCTION("""COMPUTED_VALUE"""),"ANANDA DAVA RAMADHANI") -> ANANDA DAVA RAMADHANI | F19: =VLOOKUP($B19,Userpass!$A$2:$E$3001,2,FALSE) -> tkr20259319.siswa@smkn12malang.sch.id | M19: =VLOOKUP($B19,Userpass!$A$2:$E$3001,3,FALSE) -> 8hy(fMbg
A20: 7 | B20: =IFERROR(__xludf.DUMMYFUNCTION("""COMPUTED_VALUE"""),8720.0) -> 8720 | C20: =IFERROR(__xludf.DUMMYFUNCTION("""COMPUTED_VALUE"""),"0083019599") -> 0083019599 | D20: =IFERROR(__xludf.DUMMYFUNCTION("""COMPUTED_VALUE"""),"ARIS PUTRA ARDIANSAH") -> ARIS PUTRA ARDIANSAH | E20: =IFERROR(__xludf.DUMMYFUNCTION("""COMPUTED_VALUE"""),"L") -> L | F20: =VLOOKUP($B20,Userpass!$A$2:$E$3001,2,FALSE) -> oto20248720.siswa@smkn12malang.sch.id | M20: =VLOOKUP($B20,Userpass!$A$2:$E$3001,3,FALSE) -> LA&^MyBw3PgB
A21: 8 | B21: =IFERROR(__xludf.DUMMYFUNCTION("""COMPUTED_VALUE"""),9350.0) -> 9350 | C21: =IFERROR(__xludf.DUMMYFUNCTION("""COMPUTED_VALUE"""),"0095140198") -> 0095140198 | D21: =IFERROR(__xludf.DUMMYFUNCTION("""COMPUTED_VALUE"""),"ATHALLAH SYAHMI FIRDAUS CAUNANG") -> ATHALLAH SYAHMI FIRDAUS CAUNANG | F21: =VLOOKUP($B21,Userpass!$A$2:$E$3001,2,FALSE) -> tkr20259350.siswa@smkn12malang.sch.id | M21: =VLOOKUP($B21,Userpass!$A$2:$E$3001,3,FALSE) -> 2fLMQRR&
A22: 9 | B22: =IFERROR(__xludf.DUMMYFUNCTION("""COMPUTED_VALUE"""),8752.0) -> 8752 | C22: =IFERROR(__xludf.DUMMYFUNCTION("""COMPUTED_VALUE"""),"0082093419") -> 0082093419 | D22: =IFERROR(__xludf.DUMMYFUNCTION("""COMPUTED_VALUE"""),"BAYU WAHYU SASMITO") -> BAYU WAHYU SASMITO | E22: =IFERROR(__xludf.DUMMYFUNCTION("""COMPUTED_VALUE"""),"L") -> L | F22: =VLOOKUP($B22,Userpass!$A$2:$E$3001,2,FALSE) -> oto20248752.siswa@smkn12malang.sch.id | M22: =VLOOKUP($B22,Userpass!$A$2:$E$3001,3,FALSE) -> &$=Lc_vB2fFs
A23: 10 | B23: =IFERROR(__xludf.DUMMYFUNCTION("""COMPUTED_VALUE"""),9378.0) -> 9378 | C23: =IFERROR(__xludf.DUMMYFUNCTION("""COMPUTED_VALUE"""),"0094269890") -> 0094269890 | D23: =IFERROR(__xludf.DUMMYFUNCTION("""COMPUTED_VALUE"""),"BIMA NUR ROHMAN") -> BIMA NUR ROHMAN | F23: =VLOOKUP($B23,Userpass!$A$2:$E$3001,2,FALSE) -> tkr20259378.siswa@smkn12malang.sch.id | M23: =VLOOKUP($B23,Userpass!$A$2:$E$3001,3,FALSE) -> 32y@rz4Y
A24: 11 | B24: =IFERROR(__xludf.DUMMYFUNCTION("""COMPUTED_VALUE"""),9383.0) -> 9383 | C24: =IFERROR(__xludf.DUMMYFUNCTION("""COMPUTED_VALUE"""),"0099933296") -> 0099933296 | D24: =IFERROR(__xludf.DUMMYFUNCTION("""COMPUTED_VALUE"""),"CAMELLO LAZUARDY TAMA OHARA") -> CAMELLO LAZUARDY TAMA OHARA | F24: =VLOOKUP($B24,Userpass!$A$2:$E$3001,2,FALSE) -> tkr20259383.siswa@smkn12malang.sch.id | M24: =VLOOKUP($B24,Userpass!$A$2:$E$3001,3,FALSE) -> VX3(SMvD
A25: 12 | B25: =IFERROR(__xludf.DUMMYFUNCTION("""COMPUTED_VALUE"""),9408.0) -> 9408 | C25: =IFERROR(__xludf.DUMMYFUNCTION("""COMPUTED_VALUE"""),"0088153486") -> 0088153486 | D25: =IFERROR(__xludf.DUMMYFUNCTION("""COMPUTED_VALUE"""),"DEVIN ARYA SATYA RAMADHANI") -> DEVIN ARYA SATYA RAMADHANI | F25: =VLOOKUP($B25,Userpass!$A$2:$E$3001,2,FALSE) -> tkr20259408.siswa@smkn12malang.sch.id | M25: =VLOOKUP($B25,Userpass!$A$2:$E$3001,3,FALSE) -> $YS6PVwr
A26: 13 | B26: =IFERROR(__xludf.DUMMYFUNCTION("""COMPUTED_VALUE"""),9420.0) -> 9420 | C26: =IFERROR(__xludf.DUMMYFUNCTION("""COMPUTED_VALUE"""),"0096618760") -> 0096618760 | D26: =IFERROR(__xludf.DUMMYFUNCTION("""COMPUTED_VALUE"""),"DIMAS SETYA PRATAMA") -> DIMAS SETYA PRATAMA | F26: =VLOOKUP($B26,Userpass!$A$2:$E$3001,2,FALSE) -> tkr20259420.siswa@smkn12malang.sch.id | M26: =VLOOKUP($B26,Userpass!$A$2:$E$3001,3,FALSE) -> fzYX3Rx)
A27: 14 | B27: =IFERROR(__xludf.DUMMYFUNCTION("""COMPUTED_VALUE"""),9444.0) -> 9444 | C27: =IFERROR(__xludf.DUMMYFUNCTION("""COMPUTED_VALUE"""),"3085920757") -> 3085920757 | D27: =IFERROR(__xludf.DUMMYFUNCTION("""COMPUTED_VALUE"""),"FAJAR INDRA RAMADANI") -> FAJAR INDRA RAMADANI | F27: =VLOOKUP($B27,Userpass!$A$2:$E$3001,2,FALSE) -> tkr20259444.siswa@smkn12malang.sch.id | M27: =VLOOKUP($B27,Userpass!$A$2:$E$3001,3,FALSE) -> 3SC@3sNu
A28: 15 | B28: =IFERROR(__xludf.DUMMYFUNCTION("""COMPUTED_VALUE"""),9452.0) -> 9452 | C28: =IFERROR(__xludf.DUMMYFUNCTION("""COMPUTED_VALUE"""),"3093011199") -> 3093011199 | D28: =IFERROR(__xludf.DUMMYFUNCTION("""COMPUTED_VALUE"""),"FAREL ARTA PRADITA") -> FAREL ARTA PRADITA | F28: =VLOOKUP($B28,Userpass!$A$2:$E$3001,2,FALSE) -> tkr20259452.siswa@smkn12malang.sch.id | M28: =VLOOKUP($B28,Userpass!$A$2:$E$3001,3,FALSE) -> TamJ#Yx4
A29: 16 | B29: =IFERROR(__xludf.DUMMYFUNCTION("""COMPUTED_VALUE"""),9461.0) -> 9461 | C29: =IFERROR(__xludf.DUMMYFUNCTION("""COMPUTED_VALUE"""),"0092943493") -> 0092943493 | D29: =IFERROR(__xludf.DUMMYFUNCTION("""COMPUTED_VALUE"""),"FELIZYCO ARIESTO EFFENDY") -> FELIZYCO ARIESTO EFFENDY | F29: =VLOOKUP($B29,Userpass!$A$2:$E$3001,2,FALSE) -> tkr20259461.siswa@smkn12malang.sch.id | M29: =VLOOKUP($B29,Userpass!$A$2:$E$3001,3,FALSE) -> f)E4D3n8
A30: 17 | B30: =IFERROR(__xludf.DUMMYFUNCTION("""COMPUTED_VALUE"""),9469.0) -> 9469 | C30: =IFERROR(__xludf.DUMMYFUNCTION("""COMPUTED_VALUE"""),"0107255556") -> 0107255556 | D30: =IFERROR(__xludf.DUMMYFUNCTION("""COMPUTED_VALUE"""),"GABRIEL") -> GABRIEL | F30: =VLOOKUP($B30,Userpass!$A$2:$E$3001,2,FALSE) -> tkr20259469.siswa@smkn12malang.sch.id | M30: =VLOOKUP($B30,Userpass!$A$2:$E$3001,3,FALSE) -> 2EjPXJ(v
A31: 18 | B31: =IFERROR(__xludf.DUMMYFUNCTION("""COMPUTED_VALUE"""),9480.0) -> 9480 | C31: =IFERROR(__xludf.DUMMYFUNCTION("""COMPUTED_VALUE"""),"0091523831") -> 0091523831 | D31: =IFERROR(__xludf.DUMMYFUNCTION("""COMPUTED_VALUE"""),"HANCC VITRA PRATAMA") -> HANCC VITRA PRATAMA | F31: =VLOOKUP($B31,Userpass!$A$2:$E$3001,2,FALSE) -> tkr20259480.siswa@smkn12malang.sch.id | M31: =VLOOKUP($B31,Userpass!$A$2:$E$3001,3,FALSE) -> 3tTGkH)G
A32: 19 | B32: =IFERROR(__xludf.DUMMYFUNCTION("""COMPUTED_VALUE"""),9495.0) -> 9495 | C32: =IFERROR(__xludf.DUMMYFUNCTION("""COMPUTED_VALUE"""),"0095511774") -> 0095511774 | D32: =IFERROR(__xludf.DUMMYFUNCTION("""COMPUTED_VALUE"""),"INDIGO JUDISTIRA PAMUNGKAS") -> INDIGO JUDISTIRA PAMUNGKAS | F32: =VLOOKUP($B32,Userpass!$A$2:$E$3001,2,FALSE) -> tkr20259495.siswa@smkn12malang.sch.id | M32: =VLOOKUP($B32,Userpass!$A$2:$E$3001,3,FALSE) -> N2JrhB$2
A33: 20 | B33: =IFERROR(__xludf.DUMMYFUNCTION("""COMPUTED_VALUE"""),9544.0) -> 9544 | C33: =IFERROR(__xludf.DUMMYFUNCTION("""COMPUTED_VALUE"""),"0096923961") -> 0096923961 | D33: =IFERROR(__xludf.DUMMYFUNCTION("""COMPUTED_VALUE"""),"M YOGI ALGIFAHRI") -> M YOGI ALGIFAHRI | F33: =VLOOKUP($B33,Userpass!$A$2:$E$3001,2,FALSE) -> tkr20259544.siswa@smkn12malang.sch.id | M33: =VLOOKUP($B33,Userpass!$A$2:$E$3001,3,FALSE) -> 3zCLq(Nd
A34: 21 | B34: =IFERROR(__xludf.DUMMYFUNCTION("""COMPUTED_VALUE"""),9570.0) -> 9570 | C34: =IFERROR(__xludf.DUMMYFUNCTION("""COMPUTED_VALUE"""),"0091702170") -> 0091702170 | D34: =IFERROR(__xludf.DUMMYFUNCTION("""COMPUTED_VALUE"""),"MOCH ROFIQURROCHMAN") -> MOCH ROFIQURROCHMAN | F34: =VLOOKUP($B34,Userpass!$A$2:$E$3001,2,FALSE) -> tkr20259570.siswa@smkn12malang.sch.id | M34: =VLOOKUP($B34,Userpass!$A$2:$E$3001,3,FALSE) -> w7M7(TTv
A35: 22 | B35: =IFERROR(__xludf.DUMMYFUNCTION("""COMPUTED_VALUE"""),9579.0) -> 9579 | C35: =IFERROR(__xludf.DUMMYFUNCTION("""COMPUTED_VALUE"""),"0083806353") -> 0083806353 | D35: =IFERROR(__xludf.DUMMYFUNCTION("""COMPUTED_VALUE"""),"MOCHAMMAD AFDAL ROSHAN HAQIQI") -> MOCHAMMAD AFDAL ROSHAN HAQIQI | F35: =VLOOKUP($B35,Userpass!$A$2:$E$3001,2,FALSE) -> tkr20259579.siswa@smkn12malang.sch.id | M35: =VLOOKUP($B35,Userpass!$A$2:$E$3001,3,FALSE) -> @dwbNhG7
A36: 23 | B36: =IFERROR(__xludf.DUMMYFUNCTION("""COMPUTED_VALUE"""),9584.0) -> 9584 | C36: =IFERROR(__xludf.DUMMYFUNCTION("""COMPUTED_VALUE"""),"0103590421") -> 0103590421 | D36: =IFERROR(__xludf.DUMMYFUNCTION("""COMPUTED_VALUE"""),"MOCHAMMAD MOUDI REVANSYACH") -> MOCHAMMAD MOUDI REVANSYACH | F36: =VLOOKUP($B36,Userpass!$A$2:$E$3001,2,FALSE) -> tkr20259584.siswa@smkn12malang.sch.id | M36: =VLOOKUP($B36,Userpass!$A$2:$E$3001,3,FALSE) -> Xk&VhF3e
A37: 24 | B37: =IFERROR(__xludf.DUMMYFUNCTION("""COMPUTED_VALUE"""),9593.0) -> 9593 | C37: =IFERROR(__xludf.DUMMYFUNCTION("""COMPUTED_VALUE"""),"0105657168") -> 0105657168 | D37: =IFERROR(__xludf.DUMMYFUNCTION("""COMPUTED_VALUE"""),"MOHAMAD ZAKY RAGIL JAYAMULYA") -> MOHAMAD ZAKY RAGIL JAYAMULYA | F37: =VLOOKUP($B37,Userpass!$A$2:$E$3001,2,FALSE) -> tkr20259593.siswa@smkn12malang.sch.id | M37: =VLOOKUP($B37,Userpass!$A$2:$E$3001,3,FALSE) -> 5spz9vR#
A38: 25 | B38: =IFERROR(__xludf.DUMMYFUNCTION("""COMPUTED_VALUE"""),9606.0) -> 9606 | C38: =IFERROR(__xludf.DUMMYFUNCTION("""COMPUTED_VALUE"""),"0092268438") -> 0092268438 | D38: =IFERROR(__xludf.DUMMYFUNCTION("""COMPUTED_VALUE"""),"MUHAMMAD ADITYA PRAYOGA") -> MUHAMMAD ADITYA PRAYOGA | F38: =VLOOKUP($B38,Userpass!$A$2:$E$3001,2,FALSE) -> tkr20259606.siswa@smkn12malang.sch.id | M38: =VLOOKUP($B38,Userpass!$A$2:$E$3001,3,FALSE) -> 6@22RpA6
A39: 26 | B39: =IFERROR(__xludf.DUMMYFUNCTION("""COMPUTED_VALUE"""),9622.0) -> 9622 | C39: =IFERROR(__xludf.DUMMYFUNCTION("""COMPUTED_VALUE"""),"0089948301") -> 0089948301 | D39: =IFERROR(__xludf.DUMMYFUNCTION("""COMPUTED_VALUE"""),"MUHAMMAD HAIDAR ALVINO") -> MUHAMMAD HAIDAR ALVINO | F39: =VLOOKUP($B39,Userpass!$A$2:$E$3001,2,FALSE) -> tkr20259622.siswa@smkn12malang.sch.id | M39: =VLOOKUP($B39,Userpass!$A$2:$E$3001,3,FALSE) -> Xj6cu&tY
A40: 27 | B40: =IFERROR(__xludf.DUMMYFUNCTION("""COMPUTED_VALUE"""),9633.0) -> 9633 | C40: =IFERROR(__xludf.DUMMYFUNCTION("""COMPUTED_VALUE"""),"0085548169") -> 0085548169 | D40: =IFERROR(__xludf.DUMMYFUNCTION("""COMPUTED_VALUE"""),"MUHAMMAD REIFANDY DAVIN ALFIANSYAH") -> MUHAMMAD REIFANDY DAVIN ALFIANSYAH | F40: =VLOOKUP($B40,Userpass!$A$2:$E$3001,2,FALSE) -> tkr20259633.siswa@smkn12malang.sch.id | M40: =VLOOKUP($B40,Userpass!$A$2:$E$3001,3,FALSE) -> v_8rB6cT
A41: 28 | B41: =IFERROR(__xludf.DUMMYFUNCTION("""COMPUTED_VALUE"""),9638.0) -> 9638 | C41: =IFERROR(__xludf.DUMMYFUNCTION("""COMPUTED_VALUE"""),"0106559895") -> 0106559895 | D41: =IFERROR(__xludf.DUMMYFUNCTION("""COMPUTED_VALUE"""),"MUHAMMAD ZIDAN AKBAR MAULANA") -> MUHAMMAD ZIDAN AKBAR MAULANA | F41: =VLOOKUP($B41,Userpass!$A$2:$E$3001,2,FALSE) -> tkr20259638.siswa@smkn12malang.sch.id | M41: =VLOOKUP($B41,Userpass!$A$2:$E$3001,3,FALSE) -> RY98$rFR
A42: 29 | B42: =IFERROR(__xludf.DUMMYFUNCTION("""COMPUTED_VALUE"""),9643.0) -> 9643 | C42: =IFERROR(__xludf.DUMMYFUNCTION("""COMPUTED_VALUE"""),"3108151919") -> 3108151919 | D42: =IFERROR(__xludf.DUMMYFUNCTION("""COMPUTED_VALUE"""),"MUKHAMAD IMZA AL FAIZ") -> MUKHAMAD IMZA AL FAIZ | F42: =VLOOKUP($B42,Userpass!$A$2:$E$3001,2,FALSE) -> tkr20259643.siswa@smkn12malang.sch.id | M42: =VLOOKUP($B42,Userpass!$A$2:$E$3001,3,FALSE) -> WJ@z8YFQ
A43: 30 | B43: =IFERROR(__xludf.DUMMYFUNCTION("""COMPUTED_VALUE"""),9699.0) -> 9699 | C43: =IFERROR(__xludf.DUMMYFUNCTION("""COMPUTED_VALUE"""),"0093328670") -> 0093328670 | D43: =IFERROR(__xludf.DUMMYFUNCTION("""COMPUTED_VALUE"""),"RAFA OCTAVIANO PRATAMA") -> RAFA OCTAVIANO PRATAMA | F43: =VLOOKUP($B43,Userpass!$A$2:$E$3001,2,FALSE) -> tkr20259699.siswa@smkn12malang.sch.id | M43: =VLOOKUP($B43,Userpass!$A$2:$E$3001,3,FALSE) -> fZ8wQME)
A44: 31 | B44: =IFERROR(__xludf.DUMMYFUNCTION("""COMPUTED_VALUE"""),9712.0) -> 9712 | C44: =IFERROR(__xludf.DUMMYFUNCTION("""COMPUTED_VALUE"""),"0098976870") -> 0098976870 | D44: =IFERROR(__xludf.DUMMYFUNCTION("""COMPUTED_VALUE"""),"RASYID FERDIANSYAH RAMADHAN SYAHPUTRA") -> RASYID FERDIANSYAH RAMADHAN SYAHPUTRA | F44: =VLOOKUP($B44,Userpass!$A$2:$E$3001,2,FALSE) -> tkr20259712.siswa@smkn12malang.sch.id | M44: =VLOOKUP($B44,Userpass!$A$2:$E$3001,3,FALSE) -> S#Bz4Wmv
...

Sheet CetakPenilaian
D1: PEMERINTAH PROVINSI JAWA TIMUR
D2: SMK NEGERI 12 MALANG
D3: Jl. Pahlawan, Balearjosari, Blimbing, Kota Malang, Jawa Timur 65126
D4: Telepon (0341) 400884, Faksimile (0341) 400884
D5: Laman: https://smkn12malang.sch.id, Pos-el: surat@smkn12malang.sch.id
D7: DAFTAR PESERTA DIDIK
D8: TAHUN PELAJARAN 2024/2025
D9: SEMESTER GASAL
B11: Wali Kelas: | C11: =VLOOKUP(N11,Walas!A2:B89,2,FALSE) -> YENI INDAH KURNIAWATI, M.Pd | M11: Kelas: | N11: XIIAKL2
A13: NO | B13: NIS | C13: NISN | D13: NAMA | E13: L/P | F13: D1 | G13: D2 | H13: D3 | I13: D4 | J13: D5 | K13: D6 | L13: D7 | M13: D8 | N13: D9 | O13: D10 | P13: KET
A14: 1 | B14: =IFERROR(__xludf.DUMMYFUNCTION("FILTER(MasterData!C2:F1845,MasterData!G2:G1845=N11)"),8033.0) -> 8033 | C14: =IFERROR(__xludf.DUMMYFUNCTION("""COMPUTED_VALUE"""),"0082728366") -> 0082728366 | D14: =IFERROR(__xludf.DUMMYFUNCTION("""COMPUTED_VALUE"""),"ADELIA NIZMA WARDHANI") -> ADELIA NIZMA WARDHANI | E14: =IFERROR(__xludf.DUMMYFUNCTION("""COMPUTED_VALUE"""),"P") -> P
A15: 2 | B15: =IFERROR(__xludf.DUMMYFUNCTION("""COMPUTED_VALUE"""),8076.0) -> 8076 | C15: =IFERROR(__xludf.DUMMYFUNCTION("""COMPUTED_VALUE"""),"0081539088") -> 0081539088 | D15: =IFERROR(__xludf.DUMMYFUNCTION("""COMPUTED_VALUE"""),"ALVINA AMALIA SUBHAN") -> ALVINA AMALIA SUBHAN | E15: =IFERROR(__xludf.DUMMYFUNCTION("""COMPUTED_VALUE"""),"P") -> P
A16: 3 | B16: =IFERROR(__xludf.DUMMYFUNCTION("""COMPUTED_VALUE"""),8082.0) -> 8082 | C16: =IFERROR(__xludf.DUMMYFUNCTION("""COMPUTED_VALUE"""),"0088804628") -> 0088804628 | D16: =IFERROR(__xludf.DUMMYFUNCTION("""COMPUTED_VALUE"""),"ALZENA AYU NABILA HAKIM") -> ALZENA AYU NABILA HAKIM | E16: =IFERROR(__xludf.DUMMYFUNCTION("""COMPUTED_VALUE"""),"P") -> P
A17: 4 | B17: =IFERROR(__xludf.DUMMYFUNCTION("""COMPUTED_VALUE"""),8097.0) -> 8097 | C17: =IFERROR(__xludf.DUMMYFUNCTION("""COMPUTED_VALUE"""),"0079985645") -> 0079985645 | D17: =IFERROR(__xludf.DUMMYFUNCTION("""COMPUTED_VALUE"""),"ANGGITA DWI PUSPITANINGRUM") -> ANGGITA DWI PUSPITANINGRUM | E17: =IFERROR(__xludf.DUMMYFUNCTION("""COMPUTED_VALUE"""),"P") -> P
A18: 5 | B18: =IFERROR(__xludf.DUMMYFUNCTION("""COMPUTED_VALUE"""),8102.0) -> 8102 | C18: =IFERROR(__xludf.DUMMYFUNCTION("""COMPUTED_VALUE"""),"0079739922") -> 0079739922 | D18: =IFERROR(__xludf.DUMMYFUNCTION("""COMPUTED_VALUE"""),"ANNISA NAILATUL IZZAH") -> ANNISA NAILATUL IZZAH | E18: =IFERROR(__xludf.DUMMYFUNCTION("""COMPUTED_VALUE"""),"P") -> P
A19: 6 | B19: =IFERROR(__xludf.DUMMYFUNCTION("""COMPUTED_VALUE"""),8120.0) -> 8120 | C19: =IFERROR(__xludf.DUMMYFUNCTION("""COMPUTED_VALUE"""),"0088523554") -> 0088523554 | D19: =IFERROR(__xludf.DUMMYFUNCTION("""COMPUTED_VALUE"""),"ATHIYA BILQIS AIF GHASSANI") -> ATHIYA BILQIS AIF GHASSANI | E19: =IFERROR(__xludf.DUMMYFUNCTION("""COMPUTED_VALUE"""),"P") -> P
A20: 7 | B20: =IFERROR(__xludf.DUMMYFUNCTION("""COMPUTED_VALUE"""),8125.0) -> 8125 | C20: =IFERROR(__xludf.DUMMYFUNCTION("""COMPUTED_VALUE"""),"0086121030") -> 0086121030 | D20: =IFERROR(__xludf.DUMMYFUNCTION("""COMPUTED_VALUE"""),"AYU CINTIYA NOVITA SARI") -> AYU CINTIYA NOVITA SARI | E20: =IFERROR(__xludf.DUMMYFUNCTION("""COMPUTED_VALUE"""),"P") -> P
A21: 8
A22: 9
A23: 10
A24: 11
A25: 12
A26: 13
A27: 14
A28: 15
A29: 16
A30: 17
A31: 18
A32: 19
... A49: 36
D51: Jumlah Siswa Laki-Laki : | E51: =COUNTIF($E$14:$E$49,"L") -> 0
D52: Jumlah Siswa Perempuan : | E52: =COUNTIF($E$14:$E$49,"P") -> 7
L53: Malang,
L54: Guru Pengasuh
L60: NIP.

Sheet Walas
A1: Tugas | B1: Nama GTK
A2: XAKN1 | B2: KARUNIA INDAYARTI, S.Pd
A3: XAKN2 | B3: WAHYU SURYANDARI, S.Pd
A4: XAKN3 | B4: LISSA'ADAH, S.Ag., M.Pd.I
A5: XAKN4 | B5: FAJAR ROCHANI, S.Pd
A6: XDKV1 | B6: YUNUS WARDANA, S.Kom
A7: XDKV2 | B7: ISBANDRIYAWATI, S.Pd
A8: XIAKL1 | B8: TATIK ARIFATUL KHOIRIYAH, S.Pd
A9: XIAKL2 | B9: DITA SAVITRI, S.Pd, MM
A10: XIAKL3 | B10: KAMALAT FIKA LIDINILLAH, S.Pd
A11: XIAKL4 | B11: JULA DIAN FEBRUARINA, S.Pd
A12: XIBCF1 | B12: SYAIFUL ANWAR DHARTAMUDA, M.Pd.I
... A52: XTSM2 | B52: ARIF KURNIA PUTRA, S.Pd
B53: DIYAN WAHYU ASTUTI, S.Kom
B54: A. ROSYIDATUS SAADAH, S.Pd
B55: AAN SUSANTO, S.Pd
B56: ACHMAD IMRON FANANIE, S.Pd
B57: ACHMAD KHOFIYULLOH, S.P
B58: ACHMAD SUPRAYITNO, S.Pd
B59: ANIS SETYOWATI, S.Pd
B60: ANISATU SOLIKHAH, S.Pd, Gr
B61: ANTON WIBOWO
B62: AYU PUSPARINI, S.Pd
B63: Drs. JOKO PRAMONO
B64: Drs. S. HADI ANSORI
... B86: YANI ZULKARNAIN
